<?xml version="1.0" encoding="UTF-8"?>
<!-- Generated by org.testng.reporters.JUnitReportReporter -->
<testsuite hostname="HJD11053" name="Runner.runner" tests="3" failures="0" timestamp="12 Mar 2020 06:13:04 GMT" time="16.662" errors="1">
  <testcase name="feature" time="8.723" classname="Runner.runner">
    <error type="cucumber.runtime.CucumberException" message="java.lang.AssertionError: expected:&lt;200&gt; but was:&lt;401&gt;">
      <![CDATA[cucumber.runtime.CucumberException: java.lang.AssertionError: expected:<200> but was:<401>
	at cucumber.api.testng.TestNGCucumberRunner.runCucumber(TestNGCucumberRunner.java:69)
	at cucumber.api.testng.AbstractTestNGCucumberTests.feature(AbstractTestNGCucumberTests.java:21)
	at sun.reflect.NativeMethodAccessorImpl.invoke0(Native Method)
	at sun.reflect.NativeMethodAccessorImpl.invoke(Unknown Source)
	at sun.reflect.DelegatingMethodAccessorImpl.invoke(Unknown Source)
	at java.lang.reflect.Method.invoke(Unknown Source)
	at org.testng.internal.MethodInvocationHelper.invokeMethod(MethodInvocationHelper.java:86)
	at org.testng.internal.Invoker.invokeMethod(Invoker.java:643)
	at org.testng.internal.Invoker.invokeTestMethod(Invoker.java:820)
	at org.testng.internal.Invoker.invokeTestMethods(Invoker.java:1128)
	at org.testng.internal.TestMethodWorker.invokeTestMethods(TestMethodWorker.java:129)
	at org.testng.internal.TestMethodWorker.run(TestMethodWorker.java:112)
	at org.testng.TestRunner.privateRun(TestRunner.java:782)
	at org.testng.TestRunner.run(TestRunner.java:632)
	at org.testng.SuiteRunner.runTest(SuiteRunner.java:366)
	at org.testng.SuiteRunner.runSequentially(SuiteRunner.java:361)
	at org.testng.SuiteRunner.privateRun(SuiteRunner.java:319)
	at org.testng.SuiteRunner.run(SuiteRunner.java:268)
	at org.testng.SuiteRunnerWorker.runSuite(SuiteRunnerWorker.java:52)
	at org.testng.SuiteRunnerWorker.run(SuiteRunnerWorker.java:86)
	at org.testng.TestNG.runSuitesSequentially(TestNG.java:1244)
	at org.testng.TestNG.runSuitesLocally(TestNG.java:1169)
	at org.testng.TestNG.run(TestNG.java:1064)
	at org.testng.remote.AbstractRemoteTestNG.run(AbstractRemoteTestNG.java:132)
	at org.testng.remote.RemoteTestNG.initAndRun(RemoteTestNG.java:236)
	at org.testng.remote.RemoteTestNG.main(RemoteTestNG.java:81)
Caused by: java.lang.AssertionError: expected:<200> but was:<401>
	at org.junit.Assert.fail(Assert.java:88)
	at org.junit.Assert.failNotEquals(Assert.java:743)
	at org.junit.Assert.assertEquals(Assert.java:118)
	at org.junit.Assert.assertEquals(Assert.java:555)
	at org.junit.Assert.assertEquals(Assert.java:542)
	at StepDefination.AuthenticationGetTestcases.the_server_returns_Successfully_response(AuthenticationGetTestcases.java:56)
	at âœ½.Then the server returns Successfully '401' response(AutheticationGetMethod.feature:20)
]]>
    </error>
  </testcase> <!-- feature -->
  <testcase name="feature" time="4.029" classname="Runner.runner"/>
  <testcase name="feature" time="3.910" classname="Runner.runner"/>
</testsuite> <!-- Runner.runner -->
